[2024-10-08T22:04:43.696+0000] {local_task_job_runner.py:120} INFO - ::group::Pre task execution logs
[2024-10-08T22:04:43.721+0000] {taskinstance.py:2076} INFO - Dependencies all met for dep_context=non-requeueable deps ti=<TaskInstance: load_dim_fact_6.load_dim_city scheduled__2024-10-07T00:00:00+00:00 [queued]>
[2024-10-08T22:04:43.731+0000] {taskinstance.py:2076} INFO - Dependencies all met for dep_context=requeueable deps ti=<TaskInstance: load_dim_fact_6.load_dim_city scheduled__2024-10-07T00:00:00+00:00 [queued]>
[2024-10-08T22:04:43.732+0000] {taskinstance.py:2306} INFO - Starting attempt 1 of 2
[2024-10-08T22:04:43.753+0000] {taskinstance.py:2330} INFO - Executing <Task(BigQueryInsertJobOperator): load_dim_city> on 2024-10-07 00:00:00+00:00
[2024-10-08T22:04:43.761+0000] {warnings.py:112} WARNING - /home/***/.local/lib/python3.12/site-packages/***/task/task_runner/standard_task_runner.py:62: DeprecationWarning: This process (pid=52) is multi-threaded, use of fork() may lead to deadlocks in the child.
  pid = os.fork()

[2024-10-08T22:04:43.763+0000] {standard_task_runner.py:64} INFO - Started process 63 to run task
[2024-10-08T22:04:43.767+0000] {standard_task_runner.py:90} INFO - Running: ['***', 'tasks', 'run', 'load_dim_fact_6', 'load_dim_city', 'scheduled__2024-10-07T00:00:00+00:00', '--job-id', '58', '--raw', '--subdir', 'DAGS_FOLDER/load_dim_fact.py', '--cfg-path', '/tmp/tmpwpggaccg']
[2024-10-08T22:04:43.769+0000] {standard_task_runner.py:91} INFO - Job 58: Subtask load_dim_city
[2024-10-08T22:04:43.847+0000] {task_command.py:426} INFO - Running <TaskInstance: load_dim_fact_6.load_dim_city scheduled__2024-10-07T00:00:00+00:00 [running]> on host 862ed47e0231
[2024-10-08T22:04:43.998+0000] {taskinstance.py:2648} INFO - Exporting env vars: AIRFLOW_CTX_DAG_OWNER='***' AIRFLOW_CTX_DAG_ID='load_dim_fact_6' AIRFLOW_CTX_TASK_ID='load_dim_city' AIRFLOW_CTX_EXECUTION_DATE='2024-10-07T00:00:00+00:00' AIRFLOW_CTX_TRY_NUMBER='1' AIRFLOW_CTX_DAG_RUN_ID='scheduled__2024-10-07T00:00:00+00:00'
[2024-10-08T22:04:44.000+0000] {taskinstance.py:430} INFO - ::endgroup::
[2024-10-08T22:04:44.025+0000] {taskinstance.py:441} INFO - ::group::Post task execution logs
[2024-10-08T22:04:44.040+0000] {taskinstance.py:2905} ERROR - Task failed with exception
Traceback (most recent call last):
  File "/home/airflow/.local/lib/python3.12/site-packages/airflow/models/taskinstance.py", line 465, in _execute_task
    result = _execute_callable(context=context, **execute_callable_kwargs)
             ^^^^^^^^^^^^^^^^^^^^^^^^^^^^^^^^^^^^^^^^^^^^^^^^^^^^^^^^^^^^^
  File "/home/airflow/.local/lib/python3.12/site-packages/airflow/models/taskinstance.py", line 432, in _execute_callable
    return execute_callable(context=context, **execute_callable_kwargs)
           ^^^^^^^^^^^^^^^^^^^^^^^^^^^^^^^^^^^^^^^^^^^^^^^^^^^^^^^^^^^^
  File "/home/airflow/.local/lib/python3.12/site-packages/airflow/models/baseoperator.py", line 401, in wrapper
    return func(self, *args, **kwargs)
           ^^^^^^^^^^^^^^^^^^^^^^^^^^^
  File "/home/airflow/.local/lib/python3.12/site-packages/airflow/providers/google/cloud/operators/bigquery.py", line 2939, in execute
    hook = BigQueryHook(
           ^^^^^^^^^^^^^
  File "/home/airflow/.local/lib/python3.12/site-packages/airflow/providers/google/cloud/hooks/bigquery.py", line 167, in __init__
    super().__init__(**kwargs)
  File "/home/airflow/.local/lib/python3.12/site-packages/airflow/providers/google/common/hooks/base_google.py", line 288, in __init__
    self.extras: dict = self.get_connection(self.gcp_conn_id).extra_dejson
                        ^^^^^^^^^^^^^^^^^^^^^^^^^^^^^^^^^^^^^
  File "/home/airflow/.local/lib/python3.12/site-packages/airflow/hooks/base.py", line 83, in get_connection
    conn = Connection.get_connection_from_secrets(conn_id)
           ^^^^^^^^^^^^^^^^^^^^^^^^^^^^^^^^^^^^^^^^^^^^^^^
  File "/home/airflow/.local/lib/python3.12/site-packages/airflow/models/connection.py", line 519, in get_connection_from_secrets
    raise AirflowNotFoundException(f"The conn_id `{conn_id}` isn't defined")
airflow.exceptions.AirflowNotFoundException: The conn_id `google_cloud_default` isn't defined
[2024-10-08T22:04:44.047+0000] {taskinstance.py:1206} INFO - Marking task as UP_FOR_RETRY. dag_id=load_dim_fact_6, task_id=load_dim_city, run_id=scheduled__2024-10-07T00:00:00+00:00, execution_date=20241007T000000, start_date=20241008T220443, end_date=20241008T220444
[2024-10-08T22:04:44.068+0000] {standard_task_runner.py:110} ERROR - Failed to execute job 58 for task load_dim_city (The conn_id `google_cloud_default` isn't defined; 63)
[2024-10-08T22:04:44.115+0000] {local_task_job_runner.py:243} INFO - Task exited with return code 1
[2024-10-08T22:04:44.150+0000] {taskinstance.py:3503} INFO - 0 downstream tasks scheduled from follow-on schedule check
[2024-10-08T22:04:44.153+0000] {local_task_job_runner.py:222} INFO - ::endgroup::
