[2024-10-05T05:28:21.997+0000] {local_task_job_runner.py:120} INFO - ::group::Pre task execution logs
[2024-10-05T05:28:22.028+0000] {taskinstance.py:2076} INFO - Dependencies all met for dep_context=non-requeueable deps ti=<TaskInstance: load_dim_fact_6.load_dim_city scheduled__2024-10-01T00:00:00+00:00 [queued]>
[2024-10-05T05:28:22.036+0000] {taskinstance.py:2076} INFO - Dependencies all met for dep_context=requeueable deps ti=<TaskInstance: load_dim_fact_6.load_dim_city scheduled__2024-10-01T00:00:00+00:00 [queued]>
[2024-10-05T05:28:22.037+0000] {taskinstance.py:2306} INFO - Starting attempt 2 of 2
[2024-10-05T05:28:22.064+0000] {taskinstance.py:2330} INFO - Executing <Task(BigQueryInsertJobOperator): load_dim_city> on 2024-10-01 00:00:00+00:00
[2024-10-05T05:28:22.071+0000] {warnings.py:112} WARNING - /home/***/.local/lib/python3.12/site-packages/***/task/task_runner/standard_task_runner.py:62: DeprecationWarning: This process (pid=224) is multi-threaded, use of fork() may lead to deadlocks in the child.
  pid = os.fork()

[2024-10-05T05:28:22.072+0000] {standard_task_runner.py:64} INFO - Started process 254 to run task
[2024-10-05T05:28:22.074+0000] {standard_task_runner.py:90} INFO - Running: ['***', 'tasks', 'run', 'load_dim_fact_6', 'load_dim_city', 'scheduled__2024-10-01T00:00:00+00:00', '--job-id', '29', '--raw', '--subdir', 'DAGS_FOLDER/load_dim_fact.py', '--cfg-path', '/tmp/tmpqry2fuyv']
[2024-10-05T05:28:22.075+0000] {standard_task_runner.py:91} INFO - Job 29: Subtask load_dim_city
[2024-10-05T05:28:22.130+0000] {task_command.py:426} INFO - Running <TaskInstance: load_dim_fact_6.load_dim_city scheduled__2024-10-01T00:00:00+00:00 [running]> on host 862ed47e0231
[2024-10-05T05:28:22.248+0000] {taskinstance.py:2648} INFO - Exporting env vars: AIRFLOW_CTX_DAG_OWNER='***' AIRFLOW_CTX_DAG_ID='load_dim_fact_6' AIRFLOW_CTX_TASK_ID='load_dim_city' AIRFLOW_CTX_EXECUTION_DATE='2024-10-01T00:00:00+00:00' AIRFLOW_CTX_TRY_NUMBER='2' AIRFLOW_CTX_DAG_RUN_ID='scheduled__2024-10-01T00:00:00+00:00'
[2024-10-05T05:28:22.249+0000] {taskinstance.py:430} INFO - ::endgroup::
[2024-10-05T05:28:22.257+0000] {taskinstance.py:441} INFO - ::group::Post task execution logs
[2024-10-05T05:28:22.266+0000] {taskinstance.py:2905} ERROR - Task failed with exception
Traceback (most recent call last):
  File "/home/airflow/.local/lib/python3.12/site-packages/airflow/models/taskinstance.py", line 465, in _execute_task
    result = _execute_callable(context=context, **execute_callable_kwargs)
             ^^^^^^^^^^^^^^^^^^^^^^^^^^^^^^^^^^^^^^^^^^^^^^^^^^^^^^^^^^^^^
  File "/home/airflow/.local/lib/python3.12/site-packages/airflow/models/taskinstance.py", line 432, in _execute_callable
    return execute_callable(context=context, **execute_callable_kwargs)
           ^^^^^^^^^^^^^^^^^^^^^^^^^^^^^^^^^^^^^^^^^^^^^^^^^^^^^^^^^^^^
  File "/home/airflow/.local/lib/python3.12/site-packages/airflow/models/baseoperator.py", line 401, in wrapper
    return func(self, *args, **kwargs)
           ^^^^^^^^^^^^^^^^^^^^^^^^^^^
  File "/home/airflow/.local/lib/python3.12/site-packages/airflow/providers/google/cloud/operators/bigquery.py", line 2939, in execute
    hook = BigQueryHook(
           ^^^^^^^^^^^^^
  File "/home/airflow/.local/lib/python3.12/site-packages/airflow/providers/google/cloud/hooks/bigquery.py", line 167, in __init__
    super().__init__(**kwargs)
  File "/home/airflow/.local/lib/python3.12/site-packages/airflow/providers/google/common/hooks/base_google.py", line 288, in __init__
    self.extras: dict = self.get_connection(self.gcp_conn_id).extra_dejson
                        ^^^^^^^^^^^^^^^^^^^^^^^^^^^^^^^^^^^^^
  File "/home/airflow/.local/lib/python3.12/site-packages/airflow/hooks/base.py", line 83, in get_connection
    conn = Connection.get_connection_from_secrets(conn_id)
           ^^^^^^^^^^^^^^^^^^^^^^^^^^^^^^^^^^^^^^^^^^^^^^^
  File "/home/airflow/.local/lib/python3.12/site-packages/airflow/models/connection.py", line 519, in get_connection_from_secrets
    raise AirflowNotFoundException(f"The conn_id `{conn_id}` isn't defined")
airflow.exceptions.AirflowNotFoundException: The conn_id `google_cloud_default` isn't defined
[2024-10-05T05:28:22.271+0000] {taskinstance.py:1206} INFO - Marking task as FAILED. dag_id=load_dim_fact_6, task_id=load_dim_city, run_id=scheduled__2024-10-01T00:00:00+00:00, execution_date=20241001T000000, start_date=20241005T052822, end_date=20241005T052822
[2024-10-05T05:28:22.283+0000] {standard_task_runner.py:110} ERROR - Failed to execute job 29 for task load_dim_city (The conn_id `google_cloud_default` isn't defined; 254)
[2024-10-05T05:28:22.297+0000] {local_task_job_runner.py:243} INFO - Task exited with return code 1
[2024-10-05T05:28:22.316+0000] {taskinstance.py:3503} INFO - 0 downstream tasks scheduled from follow-on schedule check
[2024-10-05T05:28:22.318+0000] {local_task_job_runner.py:222} INFO - ::endgroup::
