[2024-10-07T04:45:58.398+0000] {local_task_job_runner.py:120} INFO - ::group::Pre task execution logs
[2024-10-07T04:45:58.412+0000] {taskinstance.py:2076} INFO - Dependencies all met for dep_context=non-requeueable deps ti=<TaskInstance: load_dim_fact_6.load_dim_product scheduled__2024-10-05T00:00:00+00:00 [queued]>
[2024-10-07T04:45:58.419+0000] {taskinstance.py:2076} INFO - Dependencies all met for dep_context=requeueable deps ti=<TaskInstance: load_dim_fact_6.load_dim_product scheduled__2024-10-05T00:00:00+00:00 [queued]>
[2024-10-07T04:45:58.419+0000] {taskinstance.py:2306} INFO - Starting attempt 2 of 2
[2024-10-07T04:45:58.433+0000] {taskinstance.py:2330} INFO - Executing <Task(BigQueryInsertJobOperator): load_dim_product> on 2024-10-05 00:00:00+00:00
[2024-10-07T04:45:58.439+0000] {warnings.py:112} WARNING - /home/***/.local/lib/python3.12/site-packages/***/task/task_runner/standard_task_runner.py:62: DeprecationWarning: This process (pid=151) is multi-threaded, use of fork() may lead to deadlocks in the child.
  pid = os.fork()

[2024-10-07T04:45:58.440+0000] {standard_task_runner.py:64} INFO - Started process 162 to run task
[2024-10-07T04:45:58.440+0000] {standard_task_runner.py:90} INFO - Running: ['***', 'tasks', 'run', 'load_dim_fact_6', 'load_dim_product', 'scheduled__2024-10-05T00:00:00+00:00', '--job-id', '51', '--raw', '--subdir', 'DAGS_FOLDER/load_dim_fact.py', '--cfg-path', '/tmp/tmpqgk4rtob']
[2024-10-07T04:45:58.441+0000] {standard_task_runner.py:91} INFO - Job 51: Subtask load_dim_product
[2024-10-07T04:45:58.479+0000] {task_command.py:426} INFO - Running <TaskInstance: load_dim_fact_6.load_dim_product scheduled__2024-10-05T00:00:00+00:00 [running]> on host 862ed47e0231
[2024-10-07T04:45:58.546+0000] {taskinstance.py:2648} INFO - Exporting env vars: AIRFLOW_CTX_DAG_OWNER='***' AIRFLOW_CTX_DAG_ID='load_dim_fact_6' AIRFLOW_CTX_TASK_ID='load_dim_product' AIRFLOW_CTX_EXECUTION_DATE='2024-10-05T00:00:00+00:00' AIRFLOW_CTX_TRY_NUMBER='2' AIRFLOW_CTX_DAG_RUN_ID='scheduled__2024-10-05T00:00:00+00:00'
[2024-10-07T04:45:58.547+0000] {taskinstance.py:430} INFO - ::endgroup::
[2024-10-07T04:45:58.552+0000] {taskinstance.py:441} INFO - ::group::Post task execution logs
[2024-10-07T04:45:58.558+0000] {taskinstance.py:2905} ERROR - Task failed with exception
Traceback (most recent call last):
  File "/home/airflow/.local/lib/python3.12/site-packages/airflow/models/taskinstance.py", line 465, in _execute_task
    result = _execute_callable(context=context, **execute_callable_kwargs)
             ^^^^^^^^^^^^^^^^^^^^^^^^^^^^^^^^^^^^^^^^^^^^^^^^^^^^^^^^^^^^^
  File "/home/airflow/.local/lib/python3.12/site-packages/airflow/models/taskinstance.py", line 432, in _execute_callable
    return execute_callable(context=context, **execute_callable_kwargs)
           ^^^^^^^^^^^^^^^^^^^^^^^^^^^^^^^^^^^^^^^^^^^^^^^^^^^^^^^^^^^^
  File "/home/airflow/.local/lib/python3.12/site-packages/airflow/models/baseoperator.py", line 401, in wrapper
    return func(self, *args, **kwargs)
           ^^^^^^^^^^^^^^^^^^^^^^^^^^^
  File "/home/airflow/.local/lib/python3.12/site-packages/airflow/providers/google/cloud/operators/bigquery.py", line 2939, in execute
    hook = BigQueryHook(
           ^^^^^^^^^^^^^
  File "/home/airflow/.local/lib/python3.12/site-packages/airflow/providers/google/cloud/hooks/bigquery.py", line 167, in __init__
    super().__init__(**kwargs)
  File "/home/airflow/.local/lib/python3.12/site-packages/airflow/providers/google/common/hooks/base_google.py", line 288, in __init__
    self.extras: dict = self.get_connection(self.gcp_conn_id).extra_dejson
                        ^^^^^^^^^^^^^^^^^^^^^^^^^^^^^^^^^^^^^
  File "/home/airflow/.local/lib/python3.12/site-packages/airflow/hooks/base.py", line 83, in get_connection
    conn = Connection.get_connection_from_secrets(conn_id)
           ^^^^^^^^^^^^^^^^^^^^^^^^^^^^^^^^^^^^^^^^^^^^^^^
  File "/home/airflow/.local/lib/python3.12/site-packages/airflow/models/connection.py", line 519, in get_connection_from_secrets
    raise AirflowNotFoundException(f"The conn_id `{conn_id}` isn't defined")
airflow.exceptions.AirflowNotFoundException: The conn_id `google_cloud_default` isn't defined
[2024-10-07T04:45:58.563+0000] {taskinstance.py:1206} INFO - Marking task as FAILED. dag_id=load_dim_fact_6, task_id=load_dim_product, run_id=scheduled__2024-10-05T00:00:00+00:00, execution_date=20241005T000000, start_date=20241007T044558, end_date=20241007T044558
[2024-10-07T04:45:58.572+0000] {standard_task_runner.py:110} ERROR - Failed to execute job 51 for task load_dim_product (The conn_id `google_cloud_default` isn't defined; 162)
[2024-10-07T04:45:58.613+0000] {local_task_job_runner.py:243} INFO - Task exited with return code 1
[2024-10-07T04:45:58.626+0000] {taskinstance.py:3503} INFO - 0 downstream tasks scheduled from follow-on schedule check
[2024-10-07T04:45:58.627+0000] {local_task_job_runner.py:222} INFO - ::endgroup::
