[2024-10-16T23:18:38.046+0000] {local_task_job_runner.py:120} INFO - ::group::Pre task execution logs
[2024-10-16T23:18:38.065+0000] {taskinstance.py:2076} INFO - Dependencies all met for dep_context=non-requeueable deps ti=<TaskInstance: load_dim_fact_6.load_dim_customer scheduled__2024-10-15T00:00:00+00:00 [queued]>
[2024-10-16T23:18:38.074+0000] {taskinstance.py:2076} INFO - Dependencies all met for dep_context=requeueable deps ti=<TaskInstance: load_dim_fact_6.load_dim_customer scheduled__2024-10-15T00:00:00+00:00 [queued]>
[2024-10-16T23:18:38.074+0000] {taskinstance.py:2306} INFO - Starting attempt 1 of 2
[2024-10-16T23:18:38.089+0000] {taskinstance.py:2330} INFO - Executing <Task(BigQueryInsertJobOperator): load_dim_customer> on 2024-10-15 00:00:00+00:00
[2024-10-16T23:18:38.097+0000] {warnings.py:112} WARNING - /home/***/.local/lib/python3.12/site-packages/***/task/task_runner/standard_task_runner.py:62: DeprecationWarning: This process (pid=111) is multi-threaded, use of fork() may lead to deadlocks in the child.
  pid = os.fork()

[2024-10-16T23:18:38.098+0000] {standard_task_runner.py:64} INFO - Started process 133 to run task
[2024-10-16T23:18:38.098+0000] {standard_task_runner.py:90} INFO - Running: ['***', 'tasks', 'run', 'load_dim_fact_6', 'load_dim_customer', 'scheduled__2024-10-15T00:00:00+00:00', '--job-id', '84', '--raw', '--subdir', 'DAGS_FOLDER/load_dim_fact.py', '--cfg-path', '/tmp/tmpbzf0oj7d']
[2024-10-16T23:18:38.099+0000] {standard_task_runner.py:91} INFO - Job 84: Subtask load_dim_customer
[2024-10-16T23:18:38.149+0000] {task_command.py:426} INFO - Running <TaskInstance: load_dim_fact_6.load_dim_customer scheduled__2024-10-15T00:00:00+00:00 [running]> on host 862ed47e0231
[2024-10-16T23:18:38.252+0000] {taskinstance.py:2648} INFO - Exporting env vars: AIRFLOW_CTX_DAG_OWNER='***' AIRFLOW_CTX_DAG_ID='load_dim_fact_6' AIRFLOW_CTX_TASK_ID='load_dim_customer' AIRFLOW_CTX_EXECUTION_DATE='2024-10-15T00:00:00+00:00' AIRFLOW_CTX_TRY_NUMBER='1' AIRFLOW_CTX_DAG_RUN_ID='scheduled__2024-10-15T00:00:00+00:00'
[2024-10-16T23:18:38.253+0000] {taskinstance.py:430} INFO - ::endgroup::
[2024-10-16T23:18:38.262+0000] {taskinstance.py:441} INFO - ::group::Post task execution logs
[2024-10-16T23:18:38.270+0000] {taskinstance.py:2905} ERROR - Task failed with exception
Traceback (most recent call last):
  File "/home/airflow/.local/lib/python3.12/site-packages/airflow/models/taskinstance.py", line 465, in _execute_task
    result = _execute_callable(context=context, **execute_callable_kwargs)
             ^^^^^^^^^^^^^^^^^^^^^^^^^^^^^^^^^^^^^^^^^^^^^^^^^^^^^^^^^^^^^
  File "/home/airflow/.local/lib/python3.12/site-packages/airflow/models/taskinstance.py", line 432, in _execute_callable
    return execute_callable(context=context, **execute_callable_kwargs)
           ^^^^^^^^^^^^^^^^^^^^^^^^^^^^^^^^^^^^^^^^^^^^^^^^^^^^^^^^^^^^
  File "/home/airflow/.local/lib/python3.12/site-packages/airflow/models/baseoperator.py", line 401, in wrapper
    return func(self, *args, **kwargs)
           ^^^^^^^^^^^^^^^^^^^^^^^^^^^
  File "/home/airflow/.local/lib/python3.12/site-packages/airflow/providers/google/cloud/operators/bigquery.py", line 2939, in execute
    hook = BigQueryHook(
           ^^^^^^^^^^^^^
  File "/home/airflow/.local/lib/python3.12/site-packages/airflow/providers/google/cloud/hooks/bigquery.py", line 167, in __init__
    super().__init__(**kwargs)
  File "/home/airflow/.local/lib/python3.12/site-packages/airflow/providers/google/common/hooks/base_google.py", line 288, in __init__
    self.extras: dict = self.get_connection(self.gcp_conn_id).extra_dejson
                        ^^^^^^^^^^^^^^^^^^^^^^^^^^^^^^^^^^^^^
  File "/home/airflow/.local/lib/python3.12/site-packages/airflow/hooks/base.py", line 83, in get_connection
    conn = Connection.get_connection_from_secrets(conn_id)
           ^^^^^^^^^^^^^^^^^^^^^^^^^^^^^^^^^^^^^^^^^^^^^^^
  File "/home/airflow/.local/lib/python3.12/site-packages/airflow/models/connection.py", line 519, in get_connection_from_secrets
    raise AirflowNotFoundException(f"The conn_id `{conn_id}` isn't defined")
airflow.exceptions.AirflowNotFoundException: The conn_id `google_cloud_default` isn't defined
[2024-10-16T23:18:38.276+0000] {taskinstance.py:1206} INFO - Marking task as UP_FOR_RETRY. dag_id=load_dim_fact_6, task_id=load_dim_customer, run_id=scheduled__2024-10-15T00:00:00+00:00, execution_date=20241015T000000, start_date=20241016T231838, end_date=20241016T231838
[2024-10-16T23:18:38.289+0000] {standard_task_runner.py:110} ERROR - Failed to execute job 84 for task load_dim_customer (The conn_id `google_cloud_default` isn't defined; 133)
[2024-10-16T23:18:38.312+0000] {local_task_job_runner.py:243} INFO - Task exited with return code 1
[2024-10-16T23:18:38.334+0000] {taskinstance.py:3503} INFO - 0 downstream tasks scheduled from follow-on schedule check
[2024-10-16T23:18:38.335+0000] {local_task_job_runner.py:222} INFO - ::endgroup::
